2025-02-14 15:28:33,736 - my_logger - ERROR - Rollback session: [Errno -3] Temporary failure in name resolution
2025-02-14 15:30:11,629 - my_logger - ERROR - Rollback session: 'AsyncSession' object has no attribute 'is_dirty'
2025-02-14 15:30:11,645 - my_logger - ERROR - Rollback session: 'AsyncSession' object has no attribute 'is_dirty'
2025-02-14 15:30:20,484 - my_logger - ERROR - Rollback session: 'AsyncSession' object has no attribute 'is_dirty'
2025-02-14 15:30:23,782 - my_logger - ERROR - Rollback session: 'AsyncSession' object has no attribute 'is_dirty'
2025-02-14 15:30:56,171 - my_logger - ERROR - Rollback session: 'AsyncSession' object has no attribute 'is_dirty'
2025-02-14 15:31:54,638 - my_logger - ERROR - Rollback session: 'AsyncSession' object has no attribute 'is_dirty'
2025-02-14 15:40:30,220 - my_logger - ERROR - Rollback session: 'AsyncSession' object has no attribute 'dirt'
2025-02-14 15:43:49,796 - my_logger - ERROR - Rollback session: 'sqlalchemy.cyextension.collections.IdentitySet' object is not callable
2025-02-14 15:44:27,480 - my_logger - DEBUG - No changes, no need to commit.
2025-02-14 15:44:38,129 - my_logger - DEBUG - No changes, no need to commit.
2025-02-14 15:44:45,700 - my_logger - DEBUG - No changes, no need to commit.
2025-02-14 15:44:49,562 - my_logger - DEBUG - No changes, no need to commit.
2025-02-14 15:44:51,831 - my_logger - DEBUG - No changes, no need to commit.
2025-02-14 15:45:00,619 - my_logger - DEBUG - No changes, no need to commit.
2025-02-14 15:45:00,822 - my_logger - DEBUG - No changes, no need to commit.
2025-02-14 15:45:05,569 - my_logger - ERROR - Rollback session: When initializing mapper Mapper[Order(orders)], expression 'OrderProduct' failed to locate a name ('OrderProduct'). If this is a class name, consider adding this relationship() to the <class 'app.models.orders.Order'> class after both dependent classes have been defined.
2025-02-14 15:47:39,736 - my_logger - DEBUG - No changes, no need to commit.
2025-02-14 15:47:50,051 - my_logger - DEBUG - No changes, no need to commit.
2025-02-14 15:47:50,237 - my_logger - DEBUG - No changes, no need to commit.
2025-02-14 15:47:54,967 - my_logger - ERROR - Rollback session: When initializing mapper Mapper[Product(products)], expression 'OrderProduct' failed to locate a name ('OrderProduct'). If this is a class name, consider adding this relationship() to the <class 'app.models.products.Product'> class after both dependent classes have been defined.
2025-02-14 15:48:18,867 - my_logger - DEBUG - No changes, no need to commit.
2025-02-14 15:48:26,163 - my_logger - DEBUG - No changes, no need to commit.
2025-02-14 15:48:26,339 - my_logger - DEBUG - No changes, no need to commit.
2025-02-14 15:48:30,053 - my_logger - ERROR - Rollback session: Mapper 'Mapper[OrdersProducts(orders_products)]' has no property 'order'.  If this property was indicated from other mappers or configure events, ensure registry.configure() has been called.
2025-02-14 15:50:10,508 - my_logger - DEBUG - No changes, no need to commit.
2025-02-14 15:50:16,671 - my_logger - DEBUG - No changes, no need to commit.
2025-02-14 15:50:16,774 - my_logger - DEBUG - No changes, no need to commit.
2025-02-14 15:50:21,122 - my_logger - DEBUG - Session is dirty or in transaction. Commit!
2025-02-14 15:56:58,359 - my_logger - DEBUG - No changes, no need to commit.
2025-02-14 15:56:58,471 - my_logger - DEBUG - No changes, no need to commit.
2025-02-14 15:57:02,998 - my_logger - DEBUG - No changes, no need to commit.
2025-02-14 15:57:03,100 - my_logger - DEBUG - No changes, no need to commit.
2025-02-14 15:57:54,605 - my_logger - ERROR - Rollback session: Unable to apply constraint 'max_length' to supplied value 2
2025-02-14 15:57:56,757 - my_logger - ERROR - Rollback session: Unable to apply constraint 'max_length' to supplied value 2
2025-02-14 16:02:56,479 - my_logger - ERROR - Rollback session: (sqlalchemy.dialects.postgresql.asyncpg.Error) <class 'asyncpg.exceptions.DataError'>: invalid input for query argument $2: 2 (expected str, got int)
[SQL: INSERT INTO products (created_at, product_name, price, cost, stock) VALUES (now(), $1::VARCHAR, $2::VARCHAR, $3::VARCHAR, $4::VARCHAR) RETURNING products.id, products.created_at, products.product_name, products.price, products.cost, products.stock]
[parameters: ('Iphone 11', 2, 1, 0)]
(Backgro
2025-02-14 16:03:33,019 - my_logger - DEBUG - No changes, no need to commit.
2025-02-14 16:03:33,133 - my_logger - DEBUG - No changes, no need to commit.
2025-02-14 16:06:43,787 - my_logger - DEBUG - No changes, no need to commit.
2025-02-14 16:06:43,902 - my_logger - DEBUG - No changes, no need to commit.
2025-02-14 16:07:22,052 - my_logger - ERROR - Rollback session: (sqlalchemy.dialects.postgresql.asyncpg.Error) <class 'asyncpg.exceptions.DataError'>: invalid input for query argument $2: 1 (expected str, got int)
[SQL: INSERT INTO products (created_at, product_name, price, cost, stock) VALUES (now(), $1::VARCHAR, $2::VARCHAR, $3::VARCHAR, $4::VARCHAR) RETURNING products.id, products.created_at, products.product_name, products.price, products.cost, products.stock]
[parameters: ('string', 1, 1, 1)]
(Background
2025-02-14 16:11:33,934 - my_logger - DEBUG - Session is dirty or in transaction. Commit!
2025-02-14 16:12:18,023 - my_logger - DEBUG - Session is dirty or in transaction. Commit!
2025-02-14 16:12:45,423 - my_logger - ERROR - Rollback session: module 'app.crud.order_product' has no attribute 'create'
2025-02-14 16:17:38,552 - my_logger - ERROR - Rollback session: (sqlalchemy.dialects.postgresql.asyncpg.Error) <class 'asyncpg.exceptions.DataError'>: invalid input for query argument $3: 100 (expected str, got int)
[SQL: INSERT INTO orders_products (created_at, order_id, product_id, amount) VALUES (now(), $1::BIGINT, $2::BIGINT, $3::VARCHAR) RETURNING orders_products.id, orders_products.created_at, orders_products.order_id, orders_products.product_id, orders_products.amount]
[parameters: (1, 1, 100)]
(Backgr
2025-02-14 16:18:32,865 - my_logger - DEBUG - Session is dirty or in transaction. Commit!
2025-02-14 16:21:49,614 - my_logger - ERROR - Rollback session: 'dict' object has no attribute 'model_dump'
2025-02-14 16:25:48,079 - my_logger - ERROR - Rollback session: 4 validation errors:
  {'type': 'model_attributes_type', 'loc': ('response', 0), 'msg': 'Input should be a valid dictionary or object to extract fields from', 'input': True}
  {'type': 'model_attributes_type', 'loc': ('response', 1), 'msg': 'Input should be a valid dictionary or object to extract fields from', 'input': True}
  {'type': 'model_attributes_type', 'loc': ('response', 2), 'msg': 'Input should be a valid dictionary or object to extract
2025-02-14 16:26:45,662 - my_logger - ERROR - Rollback session: 1 validation errors:
  {'type': 'model_attributes_type', 'loc': ('response', 0), 'msg': 'Input should be a valid dictionary or object to extract fields from', 'input': True}

2025-02-14 16:27:50,739 - my_logger - DEBUG - Session is dirty or in transaction. Commit!
2025-02-14 16:28:25,143 - my_logger - ERROR - Rollback session: 1 validation errors:
  {'type': 'model_attributes_type', 'loc': ('response', 0), 'msg': 'Input should be a valid dictionary or object to extract fields from', 'input': True}

2025-02-14 16:28:55,339 - my_logger - DEBUG - No changes, no need to commit.
2025-02-14 16:29:05,591 - my_logger - DEBUG - No changes, no need to commit.
2025-02-14 16:29:05,714 - my_logger - DEBUG - No changes, no need to commit.
2025-02-14 16:29:08,413 - my_logger - DEBUG - No changes, no need to commit.
2025-02-14 16:29:08,514 - my_logger - DEBUG - No changes, no need to commit.
2025-02-14 16:29:33,703 - my_logger - ERROR - Rollback session: 1 validation errors:
  {'type': 'model_attributes_type', 'loc': ('response', 0), 'msg': 'Input should be a valid dictionary or object to extract fields from', 'input': True}

2025-02-14 16:31:04,840 - my_logger - DEBUG - No changes, no need to commit.
2025-02-14 16:32:27,189 - my_logger - ERROR - Rollback session: 1 validation errors:
  {'type': 'model_attributes_type', 'loc': ('response', 0), 'msg': 'Input should be a valid dictionary or object to extract fields from', 'input': True}

2025-02-14 16:56:11,255 - my_logger - DEBUG - Session is dirty or in transaction. Commit!
2025-02-14 16:57:53,953 - my_logger - DEBUG - Session is dirty or in transaction. Commit!
2025-02-14 16:58:09,983 - my_logger - DEBUG - Session is dirty or in transaction. Commit!
2025-02-14 16:58:58,689 - my_logger - DEBUG - Session is dirty or in transaction. Commit!
2025-02-15 09:20:27,700 - my_logger - DEBUG - No changes, no need to commit.
2025-02-15 09:20:37,928 - my_logger - DEBUG - No changes, no need to commit.
2025-02-15 09:20:38,078 - my_logger - DEBUG - No changes, no need to commit.
2025-02-15 09:22:15,201 - my_logger - ERROR - Rollback session: [Errno 111] Connect call failed ('127.0.0.1', 5432)
2025-02-15 09:22:18,930 - my_logger - ERROR - Rollback session: [Errno 111] Connect call failed ('127.0.0.1', 5432)
2025-02-15 10:46:21,093 - my_logger - DEBUG - No changes, no need to commit.
2025-02-15 10:46:57,953 - my_logger - DEBUG - No changes, no need to commit.
2025-02-15 10:53:05,174 - my_logger - ERROR - Rollback session: [Errno 111] Connect call failed ('127.0.0.1', 5432)
2025-02-15 10:55:11,426 - my_logger - ERROR - Rollback session: 1 validation errors:
  {'type': 'model_attributes_type', 'loc': ('response', 0), 'msg': 'Input should be a valid dictionary or object to extract fields from', 'input': True}

2025-02-15 11:05:26,602 - my_logger - ERROR - Rollback session: 'dict' object has no attribute 'model_dump'
2025-02-15 11:05:53,077 - my_logger - ERROR - Rollback session: 1 validation errors:
  {'type': 'model_attributes_type', 'loc': ('response', 0), 'msg': 'Input should be a valid dictionary or object to extract fields from', 'input': True}

2025-02-15 11:07:18,496 - my_logger - ERROR - Rollback session: 'dict' object has no attribute 'model_dump'
2025-02-15 11:08:30,133 - my_logger - DEBUG - No changes, no need to commit.
2025-02-15 11:08:42,359 - my_logger - DEBUG - No changes, no need to commit.
2025-02-15 11:08:53,743 - my_logger - DEBUG - No changes, no need to commit.
2025-02-15 11:12:33,683 - my_logger - ERROR - Rollback session: 1 validation errors:
  {'type': 'model_attributes_type', 'loc': ('response', 0), 'msg': 'Input should be a valid dictionary or object to extract fields from', 'input': True}

2025-02-15 11:14:24,808 - my_logger - ERROR - Rollback session: 1 validation errors:
  {'type': 'model_attributes_type', 'loc': ('response', 0), 'msg': 'Input should be a valid dictionary or object to extract fields from', 'input': True}

2025-02-15 11:20:47,908 - my_logger - DEBUG - Session is dirty or in transaction. Commit!
2025-02-15 11:22:45,686 - my_logger - ERROR - Rollback session: 1 validation errors:
  {'type': 'model_attributes_type', 'loc': ('response', 0), 'msg': 'Input should be a valid dictionary or object to extract fields from', 'input': True}

2025-02-15 11:23:51,595 - my_logger - DEBUG - Session is dirty or in transaction. Commit!
2025-02-15 11:24:04,814 - my_logger - ERROR - Rollback session: 1 validation errors:
  {'type': 'model_attributes_type', 'loc': ('response', 0), 'msg': 'Input should be a valid dictionary or object to extract fields from', 'input': True}

2025-02-15 11:24:10,625 - my_logger - DEBUG - Session is dirty or in transaction. Commit!
2025-02-15 11:24:12,306 - my_logger - DEBUG - Session is dirty or in transaction. Commit!
2025-02-15 11:24:21,224 - my_logger - DEBUG - Session is dirty or in transaction. Commit!
2025-02-15 11:24:26,658 - my_logger - ERROR - Rollback session: 1 validation errors:
  {'type': 'model_attributes_type', 'loc': ('response', 0), 'msg': 'Input should be a valid dictionary or object to extract fields from', 'input': True}

2025-02-15 11:24:31,819 - my_logger - DEBUG - Session is dirty or in transaction. Commit!
2025-02-15 11:25:46,622 - my_logger - ERROR - Rollback session: 1 validation errors:
  {'type': 'model_attributes_type', 'loc': ('response', 0), 'msg': 'Input should be a valid dictionary or object to extract fields from', 'input': True}

2025-02-15 11:28:31,985 - my_logger - ERROR - Rollback session: 'ProductSchemaCreate' object has no attribute 'model'
2025-02-15 11:30:45,553 - my_logger - ERROR - Rollback session: 'ProductSchemaCreate' object has no attribute 'model'
2025-02-15 11:31:44,157 - my_logger - ERROR - Rollback session: 1 validation errors:
  {'type': 'model_attributes_type', 'loc': ('response', 0), 'msg': 'Input should be a valid dictionary or object to extract fields from', 'input': True}

2025-02-15 11:32:52,569 - my_logger - ERROR - Rollback session: 1 validation errors:
  {'type': 'model_attributes_type', 'loc': ('response', 0), 'msg': 'Input should be a valid dictionary or object to extract fields from', 'input': True}

2025-02-15 11:33:27,984 - my_logger - ERROR - Rollback session: 1 validation errors:
  {'type': 'model_attributes_type', 'loc': ('response', 0), 'msg': 'Input should be a valid dictionary or object to extract fields from', 'input': True}

2025-02-15 11:34:44,217 - my_logger - ERROR - Rollback session: 1 validation errors:
  {'type': 'model_attributes_type', 'loc': ('response', 0), 'msg': 'Input should be a valid dictionary or object to extract fields from', 'input': True}

2025-02-15 11:35:05,136 - my_logger - DEBUG - No changes, no need to commit.
2025-02-15 11:35:05,255 - my_logger - DEBUG - No changes, no need to commit.
2025-02-15 11:35:14,868 - my_logger - ERROR - Rollback session: 1 validation errors:
  {'type': 'model_attributes_type', 'loc': ('response', 0), 'msg': 'Input should be a valid dictionary or object to extract fields from', 'input': True}

2025-02-15 11:35:16,060 - my_logger - ERROR - Rollback session: 1 validation errors:
  {'type': 'model_attributes_type', 'loc': ('response', 0), 'msg': 'Input should be a valid dictionary or object to extract fields from', 'input': True}

2025-02-15 11:36:33,451 - my_logger - ERROR - Rollback session: 1 validation errors:
  {'type': 'model_attributes_type', 'loc': ('response', 0), 'msg': 'Input should be a valid dictionary or object to extract fields from', 'input': True}

2025-02-15 11:38:31,618 - my_logger - ERROR - Rollback session: This result object does not return rows. It has been closed automatically.
2025-02-15 11:39:13,426 - my_logger - ERROR - Rollback session: 1 validation errors:
  {'type': 'list_type', 'loc': ('response',), 'msg': 'Input should be a valid list', 'input': None}

2025-02-15 11:40:01,081 - my_logger - DEBUG - Session is dirty or in transaction. Commit!
2025-02-15 11:40:15,161 - my_logger - DEBUG - Session is dirty or in transaction. Commit!
2025-02-15 11:40:16,229 - my_logger - DEBUG - Session is dirty or in transaction. Commit!
2025-02-15 12:14:35,794 - my_logger - DEBUG - No changes, no need to commit.
2025-02-15 12:17:06,116 - my_logger - DEBUG - No changes, no need to commit.
2025-02-16 15:55:26,931 - my_logger - ERROR - Rollback session: (sqlalchemy.dialects.postgresql.asyncpg.ProgrammingError) <class 'asyncpg.exceptions.UndefinedTableError'>: relation "products" does not exist
[SQL: INSERT INTO products (created_at, product_name, price, cost, stock) VALUES (now(), $1::VARCHAR, $2::NUMERIC(15, 2), $3::NUMERIC(15, 2), $4::INTEGER) RETURNING products.id, products.created_at, products.product_name, products.price, products.cost, products.stock]
[parameters: ('Test Product', 100.0, 5
2025-02-16 15:55:27,449 - my_logger - ERROR - Rollback session: Task <Task pending name='starlette.middleware.base.BaseHTTPMiddleware.__call__.<locals>.call_next.<locals>.coro' coro=<BaseHTTPMiddleware.__call__.<locals>.call_next.<locals>.coro() running at /home/user/work/TestTask/.venv/lib/python3.10/site-packages/starlette/middleware/base.py:151> cb=[TaskGroup._spawn.<locals>.task_done() at /home/user/work/TestTask/.venv/lib/python3.10/site-packages/anyio/_backends/_asyncio.py:789]> got Future <Future pendi
2025-02-16 15:55:27,893 - my_logger - ERROR - Rollback session: (sqlalchemy.dialects.postgresql.asyncpg.InterfaceError) <class 'asyncpg.exceptions._base.InterfaceError'>: cannot perform operation: another operation is in progress
[SQL: INSERT INTO products (created_at, product_name, price, cost, stock) VALUES (now(), $1::VARCHAR, $2::NUMERIC(15, 2), $3::NUMERIC(15, 2), $4::INTEGER) RETURNING products.id, products.created_at, products.product_name, products.price, products.cost, products.stock]
[parameters: ('
2025-02-16 15:55:28,366 - my_logger - ERROR - Rollback session: (sqlalchemy.dialects.postgresql.asyncpg.InterfaceError) <class 'asyncpg.exceptions._base.InterfaceError'>: cannot perform operation: another operation is in progress
[SQL: INSERT INTO products (created_at, product_name, price, cost, stock) VALUES (now(), $1::VARCHAR, $2::NUMERIC(15, 2), $3::NUMERIC(15, 2), $4::INTEGER) RETURNING products.id, products.created_at, products.product_name, products.price, products.cost, products.stock]
[parameters: ('
2025-02-16 15:55:28,772 - my_logger - ERROR - Rollback session: (sqlalchemy.dialects.postgresql.asyncpg.InterfaceError) <class 'asyncpg.exceptions._base.InterfaceError'>: cannot perform operation: another operation is in progress
[SQL: INSERT INTO products (created_at, product_name, price, cost, stock) VALUES (now(), $1::VARCHAR, $2::NUMERIC(15, 2), $3::NUMERIC(15, 2), $4::INTEGER), (now(), $5::VARCHAR, $6::NUMERIC(15, 2), $7::NUMERIC(15, 2), $8::INTEGER)]
[parameters: ('Product 1', 10.0, 5.0, 50, 'Product 2'
2025-02-16 15:55:29,203 - my_logger - ERROR - Rollback session: (sqlalchemy.dialects.postgresql.asyncpg.InterfaceError) <class 'asyncpg.exceptions._base.InterfaceError'>: cannot perform operation: another operation is in progress
[SQL: SELECT count(*) AS count_1 
FROM products]
(Background on this error at: https://sqlalche.me/e/20/rvf5)
2025-02-16 16:00:12,873 - my_logger - ERROR - Rollback session: (sqlalchemy.dialects.postgresql.asyncpg.ProgrammingError) <class 'asyncpg.exceptions.UndefinedTableError'>: relation "products" does not exist
[SQL: INSERT INTO products (created_at, product_name, price, cost, stock) VALUES (now(), $1::VARCHAR, $2::NUMERIC(15, 2), $3::NUMERIC(15, 2), $4::INTEGER) RETURNING products.id, products.created_at, products.product_name, products.price, products.cost, products.stock]
[parameters: ('Test Product', 100.0, 5
2025-02-16 16:00:13,339 - my_logger - ERROR - Rollback session: Task <Task pending name='starlette.middleware.base.BaseHTTPMiddleware.__call__.<locals>.call_next.<locals>.coro' coro=<BaseHTTPMiddleware.__call__.<locals>.call_next.<locals>.coro() running at /home/user/work/TestTask/.venv/lib/python3.10/site-packages/starlette/middleware/base.py:151> cb=[TaskGroup._spawn.<locals>.task_done() at /home/user/work/TestTask/.venv/lib/python3.10/site-packages/anyio/_backends/_asyncio.py:789]> got Future <Future pendi
2025-02-16 16:00:13,739 - my_logger - ERROR - Rollback session: (sqlalchemy.dialects.postgresql.asyncpg.InterfaceError) <class 'asyncpg.exceptions._base.InterfaceError'>: cannot perform operation: another operation is in progress
[SQL: INSERT INTO products (created_at, product_name, price, cost, stock) VALUES (now(), $1::VARCHAR, $2::NUMERIC(15, 2), $3::NUMERIC(15, 2), $4::INTEGER) RETURNING products.id, products.created_at, products.product_name, products.price, products.cost, products.stock]
[parameters: ('
2025-02-16 16:00:14,170 - my_logger - ERROR - Rollback session: (sqlalchemy.dialects.postgresql.asyncpg.InterfaceError) <class 'asyncpg.exceptions._base.InterfaceError'>: cannot perform operation: another operation is in progress
[SQL: INSERT INTO products (created_at, product_name, price, cost, stock) VALUES (now(), $1::VARCHAR, $2::NUMERIC(15, 2), $3::NUMERIC(15, 2), $4::INTEGER) RETURNING products.id, products.created_at, products.product_name, products.price, products.cost, products.stock]
[parameters: ('
2025-02-16 16:00:14,538 - my_logger - ERROR - Rollback session: (sqlalchemy.dialects.postgresql.asyncpg.InterfaceError) <class 'asyncpg.exceptions._base.InterfaceError'>: cannot perform operation: another operation is in progress
[SQL: INSERT INTO products (created_at, product_name, price, cost, stock) VALUES (now(), $1::VARCHAR, $2::NUMERIC(15, 2), $3::NUMERIC(15, 2), $4::INTEGER), (now(), $5::VARCHAR, $6::NUMERIC(15, 2), $7::NUMERIC(15, 2), $8::INTEGER)]
[parameters: ('Product 1', 10.0, 5.0, 50, 'Product 2'
2025-02-16 16:00:14,937 - my_logger - ERROR - Rollback session: (sqlalchemy.dialects.postgresql.asyncpg.InterfaceError) <class 'asyncpg.exceptions._base.InterfaceError'>: cannot perform operation: another operation is in progress
[SQL: SELECT count(*) AS count_1 
FROM products]
(Background on this error at: https://sqlalche.me/e/20/rvf5)
2025-02-16 16:11:24,758 - my_logger - ERROR - Rollback session: (sqlalchemy.dialects.postgresql.asyncpg.ProgrammingError) <class 'asyncpg.exceptions.UndefinedTableError'>: relation "orders_products" does not exist
[SQL: INSERT INTO orders_products (created_at, order_id, product_id, amount) VALUES (now(), $1::BIGINT, $2::BIGINT, $3::INTEGER) RETURNING orders_products.id, orders_products.created_at, orders_products.order_id, orders_products.product_id, orders_products.amount]
[parameters: (1, 1, 5)]
(Background
2025-02-16 16:11:25,223 - my_logger - ERROR - Rollback session: Task <Task pending name='starlette.middleware.base.BaseHTTPMiddleware.__call__.<locals>.call_next.<locals>.coro' coro=<BaseHTTPMiddleware.__call__.<locals>.call_next.<locals>.coro() running at /home/user/work/TestTask/.venv/lib/python3.10/site-packages/starlette/middleware/base.py:151> cb=[TaskGroup._spawn.<locals>.task_done() at /home/user/work/TestTask/.venv/lib/python3.10/site-packages/anyio/_backends/_asyncio.py:789]> got Future <Future pendi
2025-02-16 16:11:25,621 - my_logger - ERROR - Rollback session: (sqlalchemy.dialects.postgresql.asyncpg.InterfaceError) <class 'asyncpg.exceptions._base.InterfaceError'>: cannot perform operation: another operation is in progress
[SQL: INSERT INTO orders_products (created_at, order_id, product_id, amount) VALUES (now(), $1::BIGINT, $2::BIGINT, $3::INTEGER) RETURNING orders_products.id, orders_products.created_at, orders_products.order_id, orders_products.product_id, orders_products.amount]
[parameters: (1, 1,
2025-02-16 16:11:26,053 - my_logger - ERROR - Rollback session: (sqlalchemy.dialects.postgresql.asyncpg.InterfaceError) <class 'asyncpg.exceptions._base.InterfaceError'>: cannot perform operation: another operation is in progress
[SQL: INSERT INTO orders_products (created_at, order_id, product_id, amount) VALUES (now(), $1::BIGINT, $2::BIGINT, $3::INTEGER) RETURNING orders_products.id, orders_products.created_at, orders_products.order_id, orders_products.product_id, orders_products.amount]
[parameters: (1, 1,
2025-02-16 16:11:26,487 - my_logger - ERROR - Rollback session: (sqlalchemy.dialects.postgresql.asyncpg.InterfaceError) <class 'asyncpg.exceptions._base.InterfaceError'>: cannot perform operation: another operation is in progress
[SQL: SELECT count(*) AS count_1 
FROM orders_products]
(Background on this error at: https://sqlalche.me/e/20/rvf5)
2025-02-16 16:49:51,929 - my_logger - ERROR - Unexpected error occurred: (sqlalchemy.dialects.postgresql.asyncpg.ProgrammingError) <class 'asyncpg.exceptions.UndefinedTableError'>: relation "orders_products" does not exist
[SQL: INSERT INTO orders_products (created_at, order_id, product_id, amount) VALUES (now(), $1::BIGINT, $2::BIGINT, $3::INTEGER) RETURNING orders_products.id, orders_products.created_at, orders_products.order_id, orders_products.product_id, orders_products.amount]
[parameters: (1, 1, 5)]
(Background on this error at: https://sqlalche.me/e/20/f405)
2025-02-16 16:49:51,939 - my_logger - ERROR - Unexpected error occurred: Task <Task pending name='starlette.middleware.base.BaseHTTPMiddleware.__call__.<locals>.call_next.<locals>.coro' coro=<BaseHTTPMiddleware.__call__.<locals>.call_next.<locals>.coro() running at /home/user/work/TestTask/.venv/lib/python3.10/site-packages/starlette/middleware/base.py:151> cb=[TaskGroup._spawn.<locals>.task_done() at /home/user/work/TestTask/.venv/lib/python3.10/site-packages/anyio/_backends/_asyncio.py:789]> got Future <Future pending cb=[Protocol._on_waiter_completed()]> attached to a different loop
2025-02-16 16:49:51,949 - my_logger - ERROR - Unexpected error occurred: (sqlalchemy.dialects.postgresql.asyncpg.InterfaceError) <class 'asyncpg.exceptions._base.InterfaceError'>: cannot perform operation: another operation is in progress
[SQL: INSERT INTO orders_products (created_at, order_id, product_id, amount) VALUES (now(), $1::BIGINT, $2::BIGINT, $3::INTEGER) RETURNING orders_products.id, orders_products.created_at, orders_products.order_id, orders_products.product_id, orders_products.amount]
[parameters: (1, 1, 5)]
(Background on this error at: https://sqlalche.me/e/20/rvf5)
2025-02-16 16:49:51,957 - my_logger - ERROR - Unexpected error occurred: (sqlalchemy.dialects.postgresql.asyncpg.InterfaceError) <class 'asyncpg.exceptions._base.InterfaceError'>: cannot perform operation: another operation is in progress
[SQL: INSERT INTO orders_products (created_at, order_id, product_id, amount) VALUES (now(), $1::BIGINT, $2::BIGINT, $3::INTEGER) RETURNING orders_products.id, orders_products.created_at, orders_products.order_id, orders_products.product_id, orders_products.amount]
[parameters: (1, 1, 5)]
(Background on this error at: https://sqlalche.me/e/20/rvf5)
2025-02-16 16:49:51,973 - my_logger - ERROR - Unexpected error occurred: (sqlalchemy.dialects.postgresql.asyncpg.InterfaceError) <class 'asyncpg.exceptions._base.InterfaceError'>: cannot perform operation: another operation is in progress
[SQL: INSERT INTO products (created_at, product_name, price, cost, stock) VALUES (now(), $1::VARCHAR, $2::NUMERIC(15, 2), $3::NUMERIC(15, 2), $4::INTEGER) RETURNING products.id, products.created_at, products.product_name, products.price, products.cost, products.stock]
[parameters: ('Test Product', 100.0, 50.0, 10)]
(Background on this error at: https://sqlalche.me/e/20/rvf5)
2025-02-16 16:49:51,981 - my_logger - ERROR - Unexpected error occurred: (sqlalchemy.dialects.postgresql.asyncpg.InterfaceError) <class 'asyncpg.exceptions._base.InterfaceError'>: cannot perform operation: another operation is in progress
[SQL: INSERT INTO products (created_at, product_name, price, cost, stock) VALUES (now(), $1::VARCHAR, $2::NUMERIC(15, 2), $3::NUMERIC(15, 2), $4::INTEGER) RETURNING products.id, products.created_at, products.product_name, products.price, products.cost, products.stock]
[parameters: ('Test Product', 100.0, 50.0, 10)]
(Background on this error at: https://sqlalche.me/e/20/rvf5)
2025-02-16 16:49:51,990 - my_logger - ERROR - Unexpected error occurred: (sqlalchemy.dialects.postgresql.asyncpg.InterfaceError) <class 'asyncpg.exceptions._base.InterfaceError'>: cannot perform operation: another operation is in progress
[SQL: INSERT INTO products (created_at, product_name, price, cost, stock) VALUES (now(), $1::VARCHAR, $2::NUMERIC(15, 2), $3::NUMERIC(15, 2), $4::INTEGER) RETURNING products.id, products.created_at, products.product_name, products.price, products.cost, products.stock]
[parameters: ('To Delete', 50.0, 20.0, 5)]
(Background on this error at: https://sqlalche.me/e/20/rvf5)
2025-02-16 16:49:51,998 - my_logger - ERROR - Unexpected error occurred: (sqlalchemy.dialects.postgresql.asyncpg.InterfaceError) <class 'asyncpg.exceptions._base.InterfaceError'>: cannot perform operation: another operation is in progress
[SQL: INSERT INTO products (created_at, product_name, price, cost, stock) VALUES (now(), $1::VARCHAR, $2::NUMERIC(15, 2), $3::NUMERIC(15, 2), $4::INTEGER) RETURNING products.id, products.created_at, products.product_name, products.price, products.cost, products.stock]
[parameters: ('Old Name', 10.0, 5.0, 15)]
(Background on this error at: https://sqlalche.me/e/20/rvf5)
2025-02-16 16:50:40,534 - my_logger - ERROR - Unexpected error occurred: (sqlalchemy.dialects.postgresql.asyncpg.ProgrammingError) <class 'asyncpg.exceptions.UndefinedTableError'>: relation "orders_products" does not exist
[SQL: INSERT INTO orders_products (created_at, order_id, product_id, amount) VALUES (now(), $1::BIGINT, $2::BIGINT, $3::INTEGER) RETURNING orders_products.id, orders_products.created_at, orders_products.order_id, orders_products.product_id, orders_products.amount]
[parameters: (1, 1, 5)]
(Background on this error at: https://sqlalche.me/e/20/f405)
2025-02-16 16:50:40,545 - my_logger - ERROR - Unexpected error occurred: Task <Task pending name='starlette.middleware.base.BaseHTTPMiddleware.__call__.<locals>.call_next.<locals>.coro' coro=<BaseHTTPMiddleware.__call__.<locals>.call_next.<locals>.coro() running at /home/user/work/TestTask/.venv/lib/python3.10/site-packages/starlette/middleware/base.py:151> cb=[TaskGroup._spawn.<locals>.task_done() at /home/user/work/TestTask/.venv/lib/python3.10/site-packages/anyio/_backends/_asyncio.py:789]> got Future <Future pending cb=[Protocol._on_waiter_completed()]> attached to a different loop
2025-02-16 16:50:40,554 - my_logger - ERROR - Unexpected error occurred: (sqlalchemy.dialects.postgresql.asyncpg.InterfaceError) <class 'asyncpg.exceptions._base.InterfaceError'>: cannot perform operation: another operation is in progress
[SQL: INSERT INTO orders_products (created_at, order_id, product_id, amount) VALUES (now(), $1::BIGINT, $2::BIGINT, $3::INTEGER) RETURNING orders_products.id, orders_products.created_at, orders_products.order_id, orders_products.product_id, orders_products.amount]
[parameters: (1, 1, 5)]
(Background on this error at: https://sqlalche.me/e/20/rvf5)
2025-02-16 16:50:40,563 - my_logger - ERROR - Unexpected error occurred: (sqlalchemy.dialects.postgresql.asyncpg.InterfaceError) <class 'asyncpg.exceptions._base.InterfaceError'>: cannot perform operation: another operation is in progress
[SQL: INSERT INTO orders_products (created_at, order_id, product_id, amount) VALUES (now(), $1::BIGINT, $2::BIGINT, $3::INTEGER) RETURNING orders_products.id, orders_products.created_at, orders_products.order_id, orders_products.product_id, orders_products.amount]
[parameters: (1, 1, 5)]
(Background on this error at: https://sqlalche.me/e/20/rvf5)
2025-02-16 16:50:40,581 - my_logger - ERROR - Unexpected error occurred: (sqlalchemy.dialects.postgresql.asyncpg.InterfaceError) <class 'asyncpg.exceptions._base.InterfaceError'>: cannot perform operation: another operation is in progress
[SQL: INSERT INTO products (created_at, product_name, price, cost, stock) VALUES (now(), $1::VARCHAR, $2::NUMERIC(15, 2), $3::NUMERIC(15, 2), $4::INTEGER) RETURNING products.id, products.created_at, products.product_name, products.price, products.cost, products.stock]
[parameters: ('Test Product', 100.0, 50.0, 10)]
(Background on this error at: https://sqlalche.me/e/20/rvf5)
2025-02-16 16:50:40,591 - my_logger - ERROR - Unexpected error occurred: (sqlalchemy.dialects.postgresql.asyncpg.InterfaceError) <class 'asyncpg.exceptions._base.InterfaceError'>: cannot perform operation: another operation is in progress
[SQL: INSERT INTO products (created_at, product_name, price, cost, stock) VALUES (now(), $1::VARCHAR, $2::NUMERIC(15, 2), $3::NUMERIC(15, 2), $4::INTEGER) RETURNING products.id, products.created_at, products.product_name, products.price, products.cost, products.stock]
[parameters: ('Test Product', 100.0, 50.0, 10)]
(Background on this error at: https://sqlalche.me/e/20/rvf5)
2025-02-16 16:50:40,601 - my_logger - ERROR - Unexpected error occurred: (sqlalchemy.dialects.postgresql.asyncpg.InterfaceError) <class 'asyncpg.exceptions._base.InterfaceError'>: cannot perform operation: another operation is in progress
[SQL: INSERT INTO products (created_at, product_name, price, cost, stock) VALUES (now(), $1::VARCHAR, $2::NUMERIC(15, 2), $3::NUMERIC(15, 2), $4::INTEGER) RETURNING products.id, products.created_at, products.product_name, products.price, products.cost, products.stock]
[parameters: ('To Delete', 50.0, 20.0, 5)]
(Background on this error at: https://sqlalche.me/e/20/rvf5)
2025-02-16 16:50:40,611 - my_logger - ERROR - Unexpected error occurred: (sqlalchemy.dialects.postgresql.asyncpg.InterfaceError) <class 'asyncpg.exceptions._base.InterfaceError'>: cannot perform operation: another operation is in progress
[SQL: INSERT INTO products (created_at, product_name, price, cost, stock) VALUES (now(), $1::VARCHAR, $2::NUMERIC(15, 2), $3::NUMERIC(15, 2), $4::INTEGER) RETURNING products.id, products.created_at, products.product_name, products.price, products.cost, products.stock]
[parameters: ('Old Name', 10.0, 5.0, 15)]
(Background on this error at: https://sqlalche.me/e/20/rvf5)
2025-02-16 16:50:47,607 - my_logger - ERROR - Unexpected error occurred: (sqlalchemy.dialects.postgresql.asyncpg.ProgrammingError) <class 'asyncpg.exceptions.UndefinedTableError'>: relation "orders_products" does not exist
[SQL: INSERT INTO orders_products (created_at, order_id, product_id, amount) VALUES (now(), $1::BIGINT, $2::BIGINT, $3::INTEGER) RETURNING orders_products.id, orders_products.created_at, orders_products.order_id, orders_products.product_id, orders_products.amount]
[parameters: (1, 1, 5)]
(Background on this error at: https://sqlalche.me/e/20/f405)
2025-02-16 16:50:47,621 - my_logger - ERROR - Unexpected error occurred: Task <Task pending name='starlette.middleware.base.BaseHTTPMiddleware.__call__.<locals>.call_next.<locals>.coro' coro=<BaseHTTPMiddleware.__call__.<locals>.call_next.<locals>.coro() running at /home/user/work/TestTask/.venv/lib/python3.10/site-packages/starlette/middleware/base.py:151> cb=[TaskGroup._spawn.<locals>.task_done() at /home/user/work/TestTask/.venv/lib/python3.10/site-packages/anyio/_backends/_asyncio.py:789]> got Future <Future pending cb=[Protocol._on_waiter_completed()]> attached to a different loop
2025-02-16 16:50:47,630 - my_logger - ERROR - Unexpected error occurred: (sqlalchemy.dialects.postgresql.asyncpg.InterfaceError) <class 'asyncpg.exceptions._base.InterfaceError'>: cannot perform operation: another operation is in progress
[SQL: INSERT INTO orders_products (created_at, order_id, product_id, amount) VALUES (now(), $1::BIGINT, $2::BIGINT, $3::INTEGER) RETURNING orders_products.id, orders_products.created_at, orders_products.order_id, orders_products.product_id, orders_products.amount]
[parameters: (1, 1, 5)]
(Background on this error at: https://sqlalche.me/e/20/rvf5)
2025-02-16 16:50:47,640 - my_logger - ERROR - Unexpected error occurred: (sqlalchemy.dialects.postgresql.asyncpg.InterfaceError) <class 'asyncpg.exceptions._base.InterfaceError'>: cannot perform operation: another operation is in progress
[SQL: INSERT INTO orders_products (created_at, order_id, product_id, amount) VALUES (now(), $1::BIGINT, $2::BIGINT, $3::INTEGER) RETURNING orders_products.id, orders_products.created_at, orders_products.order_id, orders_products.product_id, orders_products.amount]
[parameters: (1, 1, 5)]
(Background on this error at: https://sqlalche.me/e/20/rvf5)
2025-02-16 16:50:47,660 - my_logger - ERROR - Unexpected error occurred: (sqlalchemy.dialects.postgresql.asyncpg.InterfaceError) <class 'asyncpg.exceptions._base.InterfaceError'>: cannot perform operation: another operation is in progress
[SQL: INSERT INTO products (created_at, product_name, price, cost, stock) VALUES (now(), $1::VARCHAR, $2::NUMERIC(15, 2), $3::NUMERIC(15, 2), $4::INTEGER) RETURNING products.id, products.created_at, products.product_name, products.price, products.cost, products.stock]
[parameters: ('Test Product', 100.0, 50.0, 10)]
(Background on this error at: https://sqlalche.me/e/20/rvf5)
2025-02-16 16:50:47,670 - my_logger - ERROR - Unexpected error occurred: (sqlalchemy.dialects.postgresql.asyncpg.InterfaceError) <class 'asyncpg.exceptions._base.InterfaceError'>: cannot perform operation: another operation is in progress
[SQL: INSERT INTO products (created_at, product_name, price, cost, stock) VALUES (now(), $1::VARCHAR, $2::NUMERIC(15, 2), $3::NUMERIC(15, 2), $4::INTEGER) RETURNING products.id, products.created_at, products.product_name, products.price, products.cost, products.stock]
[parameters: ('Test Product', 100.0, 50.0, 10)]
(Background on this error at: https://sqlalche.me/e/20/rvf5)
2025-02-16 16:50:47,681 - my_logger - ERROR - Unexpected error occurred: (sqlalchemy.dialects.postgresql.asyncpg.InterfaceError) <class 'asyncpg.exceptions._base.InterfaceError'>: cannot perform operation: another operation is in progress
[SQL: INSERT INTO products (created_at, product_name, price, cost, stock) VALUES (now(), $1::VARCHAR, $2::NUMERIC(15, 2), $3::NUMERIC(15, 2), $4::INTEGER) RETURNING products.id, products.created_at, products.product_name, products.price, products.cost, products.stock]
[parameters: ('To Delete', 50.0, 20.0, 5)]
(Background on this error at: https://sqlalche.me/e/20/rvf5)
2025-02-16 16:50:47,694 - my_logger - ERROR - Unexpected error occurred: (sqlalchemy.dialects.postgresql.asyncpg.InterfaceError) <class 'asyncpg.exceptions._base.InterfaceError'>: cannot perform operation: another operation is in progress
[SQL: INSERT INTO products (created_at, product_name, price, cost, stock) VALUES (now(), $1::VARCHAR, $2::NUMERIC(15, 2), $3::NUMERIC(15, 2), $4::INTEGER) RETURNING products.id, products.created_at, products.product_name, products.price, products.cost, products.stock]
[parameters: ('Old Name', 10.0, 5.0, 15)]
(Background on this error at: https://sqlalche.me/e/20/rvf5)
2025-02-16 21:24:52,264 - my_logger - ERROR - Unexpected error occurred: (sqlalchemy.dialects.postgresql.asyncpg.ProgrammingError) <class 'asyncpg.exceptions.UndefinedTableError'>: relation "orders_products" does not exist
[SQL: INSERT INTO orders_products (created_at, order_id, product_id, amount) VALUES (now(), $1::BIGINT, $2::BIGINT, $3::INTEGER) RETURNING orders_products.id, orders_products.created_at, orders_products.order_id, orders_products.product_id, orders_products.amount]
[parameters: (1, 1, 5)]
(Background on this error at: https://sqlalche.me/e/20/f405)
2025-02-16 21:24:52,274 - my_logger - ERROR - Unexpected error occurred: Task <Task pending name='starlette.middleware.base.BaseHTTPMiddleware.__call__.<locals>.call_next.<locals>.coro' coro=<BaseHTTPMiddleware.__call__.<locals>.call_next.<locals>.coro() running at /home/user/work/TestTask/.venv/lib/python3.10/site-packages/starlette/middleware/base.py:151> cb=[TaskGroup._spawn.<locals>.task_done() at /home/user/work/TestTask/.venv/lib/python3.10/site-packages/anyio/_backends/_asyncio.py:754]> got Future <Future pending cb=[Protocol._on_waiter_completed()]> attached to a different loop
2025-02-16 21:24:52,283 - my_logger - ERROR - Unexpected error occurred: (sqlalchemy.dialects.postgresql.asyncpg.InterfaceError) <class 'asyncpg.exceptions._base.InterfaceError'>: cannot perform operation: another operation is in progress
[SQL: INSERT INTO orders_products (created_at, order_id, product_id, amount) VALUES (now(), $1::BIGINT, $2::BIGINT, $3::INTEGER) RETURNING orders_products.id, orders_products.created_at, orders_products.order_id, orders_products.product_id, orders_products.amount]
[parameters: (1, 1, 5)]
(Background on this error at: https://sqlalche.me/e/20/rvf5)
2025-02-16 21:24:52,293 - my_logger - ERROR - Unexpected error occurred: (sqlalchemy.dialects.postgresql.asyncpg.InterfaceError) <class 'asyncpg.exceptions._base.InterfaceError'>: cannot perform operation: another operation is in progress
[SQL: INSERT INTO orders_products (created_at, order_id, product_id, amount) VALUES (now(), $1::BIGINT, $2::BIGINT, $3::INTEGER) RETURNING orders_products.id, orders_products.created_at, orders_products.order_id, orders_products.product_id, orders_products.amount]
[parameters: (1, 1, 5)]
(Background on this error at: https://sqlalche.me/e/20/rvf5)
2025-02-16 21:24:52,313 - my_logger - ERROR - Unexpected error occurred: (sqlalchemy.dialects.postgresql.asyncpg.InterfaceError) <class 'asyncpg.exceptions._base.InterfaceError'>: cannot perform operation: another operation is in progress
[SQL: INSERT INTO products (created_at, product_name, price, cost, stock) VALUES (now(), $1::VARCHAR, $2::NUMERIC(15, 2), $3::NUMERIC(15, 2), $4::INTEGER) RETURNING products.id, products.created_at, products.product_name, products.price, products.cost, products.stock]
[parameters: ('Test Product', 100.0, 50.0, 10)]
(Background on this error at: https://sqlalche.me/e/20/rvf5)
2025-02-16 21:24:52,323 - my_logger - ERROR - Unexpected error occurred: (sqlalchemy.dialects.postgresql.asyncpg.InterfaceError) <class 'asyncpg.exceptions._base.InterfaceError'>: cannot perform operation: another operation is in progress
[SQL: INSERT INTO products (created_at, product_name, price, cost, stock) VALUES (now(), $1::VARCHAR, $2::NUMERIC(15, 2), $3::NUMERIC(15, 2), $4::INTEGER) RETURNING products.id, products.created_at, products.product_name, products.price, products.cost, products.stock]
[parameters: ('Test Product', 100.0, 50.0, 10)]
(Background on this error at: https://sqlalche.me/e/20/rvf5)
2025-02-16 21:24:52,332 - my_logger - ERROR - Unexpected error occurred: (sqlalchemy.dialects.postgresql.asyncpg.InterfaceError) <class 'asyncpg.exceptions._base.InterfaceError'>: cannot perform operation: another operation is in progress
[SQL: INSERT INTO products (created_at, product_name, price, cost, stock) VALUES (now(), $1::VARCHAR, $2::NUMERIC(15, 2), $3::NUMERIC(15, 2), $4::INTEGER) RETURNING products.id, products.created_at, products.product_name, products.price, products.cost, products.stock]
[parameters: ('To Delete', 50.0, 20.0, 5)]
(Background on this error at: https://sqlalche.me/e/20/rvf5)
2025-02-16 21:24:52,342 - my_logger - ERROR - Unexpected error occurred: (sqlalchemy.dialects.postgresql.asyncpg.InterfaceError) <class 'asyncpg.exceptions._base.InterfaceError'>: cannot perform operation: another operation is in progress
[SQL: INSERT INTO products (created_at, product_name, price, cost, stock) VALUES (now(), $1::VARCHAR, $2::NUMERIC(15, 2), $3::NUMERIC(15, 2), $4::INTEGER) RETURNING products.id, products.created_at, products.product_name, products.price, products.cost, products.stock]
[parameters: ('Old Name', 10.0, 5.0, 15)]
(Background on this error at: https://sqlalche.me/e/20/rvf5)
2025-02-16 22:12:02,633 - my_logger - ERROR - Unexpected error occurred: time data '13.11.2022' does not match format '%Y-%m-%d'
